Initializing Sverchok logging. Blender version 2.82 (sub 6), Sverchok version 0.6.0.0, branch master, commit f2514413
Testing: /home/portnov/.config/blender/2.82/scripts/addons_contrib/sverchok-extra/tests/references/extra_diff_ops_4.blend.gz
Testing: /home/portnov/.config/blender/2.82/scripts/addons_contrib/sverchok-extra/tests/references/extra_attractor_fields_2.blend.gz
Testing: /home/portnov/.config/blender/2.82/scripts/addons_contrib/sverchok-extra/tests/references/extra_dual_noise_1.blend.gz
Testing: /home/portnov/.config/blender/2.82/scripts/addons_contrib/sverchok-extra/tests/references/extra_voronoi3d_1.blend.gz
Testing: /home/portnov/.config/blender/2.82/scripts/addons_contrib/sverchok-extra/tests/references/extra_apply_field_list_1.blend.gz
Testing: /home/portnov/.config/blender/2.82/scripts/addons_contrib/sverchok-extra/tests/references/extra_dual_metaball_1.blend.gz
Testing: /home/portnov/.config/blender/2.82/scripts/addons_contrib/sverchok-extra/tests/references/extra_bend_along_nurbs_surface_1.blend.gz
Testing: /home/portnov/.config/blender/2.82/scripts/addons_contrib/sverchok-extra/tests/references/extra_diff_ops_5.blend.gz
Testing: /home/portnov/.config/blender/2.82/scripts/addons_contrib/sverchok-extra/tests/references/extra_merge_scalar_fields_1.blend.gz
Testing: /home/portnov/.config/blender/2.82/scripts/addons_contrib/sverchok-extra/tests/references/extra_vector_fields_1.blend.gz
Testing: /home/portnov/.config/blender/2.82/scripts/addons_contrib/sverchok-extra/tests/references/extra_generic_surface_1.blend.gz
Testing: /home/portnov/.config/blender/2.82/scripts/addons_contrib/sverchok-extra/tests/references/extra_apply_1.blend.gz
Testing: /home/portnov/.config/blender/2.82/scripts/addons_contrib/sverchok-extra/tests/references/extra_attractor_fields_8.blend.gz
Testing: /home/portnov/.config/blender/2.82/scripts/addons_contrib/sverchok-extra/tests/references/extra_diff_ops_2.blend.gz
Testing: /home/portnov/.config/blender/2.82/scripts/addons_contrib/sverchok-extra/tests/references/extra_min_surface_uv_1.blend.gz
Testing: /home/portnov/.config/blender/2.82/scripts/addons_contrib/sverchok-extra/tests/references/extra_nurbs_surf_interpolation_1.blend.gz
Testing: /home/portnov/.config/blender/2.82/scripts/addons_contrib/sverchok-extra/tests/references/extra_bivar_surface_1.blend.gz
Node Object ID Selector had exception: 'bpy_prop_collection[key]: key "Plane" not found'
Traceback (most recent call last):
  File "/home/portnov/.config/blender/2.82/scripts/addons_contrib/sverchok/core/update_system.py", line 338, in do_update_general
    node.process()
  File "/home/portnov/.config/blender/2.82/scripts/addons_contrib/sverchok/nodes/object_nodes/get_asset_properties.py", line 194, in process
    output_socket.sv_set([data_list[self.object_name]])
KeyError: 'bpy_prop_collection[key]: key "Plane" not found'
Node Object ID Selector had exception: 'bpy_prop_collection[key]: key "Plane" not found'
Traceback (most recent call last):
  File "/home/portnov/.config/blender/2.82/scripts/addons_contrib/sverchok/core/update_system.py", line 338, in do_update_general
    node.process()
  File "/home/portnov/.config/blender/2.82/scripts/addons_contrib/sverchok/nodes/object_nodes/get_asset_properties.py", line 194, in process
    output_socket.sv_set([data_list[self.object_name]])
KeyError: 'bpy_prop_collection[key]: key "Plane" not found'
Node Object ID Selector had exception: 'bpy_prop_collection[key]: key "Plane" not found'
Traceback (most recent call last):
  File "/home/portnov/.config/blender/2.82/scripts/addons_contrib/sverchok-extra/tests/process_references_tests.py", line 22, in test_import_examples
    tree.process()
  File "/home/portnov/SSD/soft/blender-2.82-902209eda527-linux-glibc217-x86_64/2.82/python/lib/python3.7/contextlib.py", line 119, in __exit__
    next(self.gen)
  File "/home/portnov/.config/blender/2.82/scripts/addons_contrib/sverchok/utils/testing.py", line 491, in assert_logs_no_errors
    self.assertFalse(has_errors, "There were some errors logged")
  File "/home/portnov/SSD/soft/blender-2.82-902209eda527-linux-glibc217-x86_64/2.82/python/lib/python3.7/unittest/case.py", line 699, in assertFalse
    raise self.failureException(msg)
AssertionError: True is not false : There were some errors logged

During handling of the above exception, another exception occurred:

Traceback (most recent call last):
  File "/home/portnov/.config/blender/2.82/scripts/addons_contrib/sverchok/core/update_system.py", line 338, in do_update_general
    node.process()
  File "/home/portnov/.config/blender/2.82/scripts/addons_contrib/sverchok/nodes/object_nodes/get_asset_properties.py", line 194, in process
    output_socket.sv_set([data_list[self.object_name]])
KeyError: 'bpy_prop_collection[key]: key "Plane" not found'
Testing: /home/portnov/.config/blender/2.82/scripts/addons_contrib/sverchok-extra/tests/references/extra_diff_ops_3.blend.gz
Testing: /home/portnov/.config/blender/2.82/scripts/addons_contrib/sverchok-extra/tests/references/extra_attractor_fields_1.blend.gz
Testing: /home/portnov/.config/blender/2.82/scripts/addons_contrib/sverchok-extra/tests/references/extra_min_sfield_1.blend.gz
Test cases result:
test_import_examples (process_references_tests.ProcessRefsTestCase) ... 
======================================================================
FAIL: test_import_examples (process_references_tests.ProcessRefsTestCase) (file='/home/portnov/.config/blender/2.82/scripts/addons_contrib/sverchok-extra/tests/references/extra_bivar_surface_1.blend.gz')
----------------------------------------------------------------------
Traceback (most recent call last):
  File "/home/portnov/.config/blender/2.82/scripts/addons_contrib/sverchok-extra/tests/process_references_tests.py", line 22, in test_import_examples
    tree.process()
  File "/home/portnov/SSD/soft/blender-2.82-902209eda527-linux-glibc217-x86_64/2.82/python/lib/python3.7/contextlib.py", line 119, in __exit__
    next(self.gen)
  File "/home/portnov/.config/blender/2.82/scripts/addons_contrib/sverchok/utils/testing.py", line 491, in assert_logs_no_errors
    self.assertFalse(has_errors, "There were some errors logged")
AssertionError: True is not false : There were some errors logged

----------------------------------------------------------------------
Ran 1 test in 69.738s

FAILED (failures=1)

